2022-12-13 02:52:31,270 django.utils.autoreload INFO     Watching for file changes with StatReloader
2022-12-13 02:56:45,135 django.utils.autoreload INFO     Watching for file changes with StatReloader
2022-12-13 02:58:02,896 django.utils.autoreload INFO     /FabricaResheniy/FabricaResheniy/settings.py changed, reloading.
2022-12-13 02:58:15,666 django.utils.autoreload INFO     Watching for file changes with StatReloader
2022-12-13 03:00:23,036 django.utils.autoreload INFO     Watching for file changes with StatReloader
2022-12-13 03:10:56,045 django.security.DisallowedHost ERROR    Invalid HTTP_HOST header: '192.168.0.119:8000'. You may need to add '192.168.0.119' to ALLOWED_HOSTS.
Traceback (most recent call last):
  File "/usr/local/lib/python3.10/site-packages/django/core/handlers/exception.py", line 55, in inner
    response = get_response(request)
  File "/usr/local/lib/python3.10/site-packages/django/utils/deprecation.py", line 135, in __call__
    response = self.process_request(request)
  File "/usr/local/lib/python3.10/site-packages/django/middleware/common.py", line 48, in process_request
    host = request.get_host()
  File "/usr/local/lib/python3.10/site-packages/django/http/request.py", line 148, in get_host
    raise DisallowedHost(msg)
django.core.exceptions.DisallowedHost: Invalid HTTP_HOST header: '192.168.0.119:8000'. You may need to add '192.168.0.119' to ALLOWED_HOSTS.
2022-12-13 03:10:56,853 django.request WARNING  Bad Request: /api/
2022-12-13 03:10:57,133 django.security.DisallowedHost ERROR    Invalid HTTP_HOST header: '192.168.0.119:8000'. You may need to add '192.168.0.119' to ALLOWED_HOSTS.
Traceback (most recent call last):
  File "/usr/local/lib/python3.10/site-packages/django/core/handlers/exception.py", line 55, in inner
    response = get_response(request)
  File "/usr/local/lib/python3.10/site-packages/django/utils/deprecation.py", line 135, in __call__
    response = self.process_request(request)
  File "/usr/local/lib/python3.10/site-packages/django/middleware/common.py", line 48, in process_request
    host = request.get_host()
  File "/usr/local/lib/python3.10/site-packages/django/http/request.py", line 148, in get_host
    raise DisallowedHost(msg)
django.core.exceptions.DisallowedHost: Invalid HTTP_HOST header: '192.168.0.119:8000'. You may need to add '192.168.0.119' to ALLOWED_HOSTS.
2022-12-13 03:10:57,243 django.request WARNING  Bad Request: /favicon.ico
2022-12-13 03:10:57,939 django.security.DisallowedHost ERROR    Invalid HTTP_HOST header: '192.168.0.119:8000'. You may need to add '192.168.0.119' to ALLOWED_HOSTS.
Traceback (most recent call last):
  File "/usr/local/lib/python3.10/site-packages/django/core/handlers/exception.py", line 55, in inner
    response = get_response(request)
  File "/usr/local/lib/python3.10/site-packages/django/utils/deprecation.py", line 135, in __call__
    response = self.process_request(request)
  File "/usr/local/lib/python3.10/site-packages/django/middleware/common.py", line 48, in process_request
    host = request.get_host()
  File "/usr/local/lib/python3.10/site-packages/django/http/request.py", line 148, in get_host
    raise DisallowedHost(msg)
django.core.exceptions.DisallowedHost: Invalid HTTP_HOST header: '192.168.0.119:8000'. You may need to add '192.168.0.119' to ALLOWED_HOSTS.
2022-12-13 03:10:58,333 django.request WARNING  Bad Request: /api/
2022-12-13 03:11:24,483 django.security.DisallowedHost ERROR    Invalid HTTP_HOST header: '192.168.0.119:8000'. You may need to add '192.168.0.119' to ALLOWED_HOSTS.
Traceback (most recent call last):
  File "/usr/local/lib/python3.10/site-packages/django/core/handlers/exception.py", line 55, in inner
    response = get_response(request)
  File "/usr/local/lib/python3.10/site-packages/django/utils/deprecation.py", line 135, in __call__
    response = self.process_request(request)
  File "/usr/local/lib/python3.10/site-packages/django/middleware/common.py", line 48, in process_request
    host = request.get_host()
  File "/usr/local/lib/python3.10/site-packages/django/http/request.py", line 148, in get_host
    raise DisallowedHost(msg)
django.core.exceptions.DisallowedHost: Invalid HTTP_HOST header: '192.168.0.119:8000'. You may need to add '192.168.0.119' to ALLOWED_HOSTS.
2022-12-13 03:11:24,585 django.request WARNING  Bad Request: /api/
2022-12-13 03:12:08,088 django.security.DisallowedHost ERROR    Invalid HTTP_HOST header: '0.0.0.0:8000'. You may need to add '0.0.0.0' to ALLOWED_HOSTS.
Traceback (most recent call last):
  File "/usr/local/lib/python3.10/site-packages/django/core/handlers/exception.py", line 55, in inner
    response = get_response(request)
  File "/usr/local/lib/python3.10/site-packages/django/utils/deprecation.py", line 135, in __call__
    response = self.process_request(request)
  File "/usr/local/lib/python3.10/site-packages/django/middleware/common.py", line 48, in process_request
    host = request.get_host()
  File "/usr/local/lib/python3.10/site-packages/django/http/request.py", line 148, in get_host
    raise DisallowedHost(msg)
django.core.exceptions.DisallowedHost: Invalid HTTP_HOST header: '0.0.0.0:8000'. You may need to add '0.0.0.0' to ALLOWED_HOSTS.
2022-12-13 03:12:08,204 django.request WARNING  Bad Request: /api/mailing/1/
2022-12-13 03:12:18,892 django.request ERROR    Internal Server Error: /api/mailing/1/
Traceback (most recent call last):
  File "/usr/local/lib/python3.10/site-packages/django/db/backends/utils.py", line 89, in _execute
    return self.cursor.execute(sql, params)
  File "/usr/local/lib/python3.10/site-packages/django/db/backends/sqlite3/base.py", line 357, in execute
    return Database.Cursor.execute(self, query, params)
sqlite3.OperationalError: no such table: mailing_mailing

The above exception was the direct cause of the following exception:

Traceback (most recent call last):
  File "/usr/local/lib/python3.10/site-packages/django/core/handlers/exception.py", line 55, in inner
    response = get_response(request)
  File "/usr/local/lib/python3.10/site-packages/django/core/handlers/base.py", line 197, in _get_response
    response = wrapped_callback(request, *callback_args, **callback_kwargs)
  File "/usr/local/lib/python3.10/site-packages/django/views/decorators/csrf.py", line 54, in wrapped_view
    return view_func(*args, **kwargs)
  File "/usr/local/lib/python3.10/site-packages/rest_framework/viewsets.py", line 125, in view
    return self.dispatch(request, *args, **kwargs)
  File "/usr/local/lib/python3.10/site-packages/rest_framework/views.py", line 509, in dispatch
    response = self.handle_exception(exc)
  File "/usr/local/lib/python3.10/site-packages/rest_framework/views.py", line 469, in handle_exception
    self.raise_uncaught_exception(exc)
  File "/usr/local/lib/python3.10/site-packages/rest_framework/views.py", line 480, in raise_uncaught_exception
    raise exc
  File "/usr/local/lib/python3.10/site-packages/rest_framework/views.py", line 506, in dispatch
    response = handler(request, *args, **kwargs)
  File "/usr/local/lib/python3.10/site-packages/rest_framework/mixins.py", line 54, in retrieve
    instance = self.get_object()
  File "/usr/local/lib/python3.10/site-packages/rest_framework/generics.py", line 96, in get_object
    obj = get_object_or_404(queryset, **filter_kwargs)
  File "/usr/local/lib/python3.10/site-packages/rest_framework/generics.py", line 19, in get_object_or_404
    return _get_object_or_404(queryset, *filter_args, **filter_kwargs)
  File "/usr/local/lib/python3.10/site-packages/django/shortcuts.py", line 85, in get_object_or_404
    return queryset.get(*args, **kwargs)
  File "/usr/local/lib/python3.10/site-packages/django/db/models/query.py", line 646, in get
    num = len(clone)
  File "/usr/local/lib/python3.10/site-packages/django/db/models/query.py", line 376, in __len__
    self._fetch_all()
  File "/usr/local/lib/python3.10/site-packages/django/db/models/query.py", line 1866, in _fetch_all
    self._result_cache = list(self._iterable_class(self))
  File "/usr/local/lib/python3.10/site-packages/django/db/models/query.py", line 87, in __iter__
    results = compiler.execute_sql(
  File "/usr/local/lib/python3.10/site-packages/django/db/models/sql/compiler.py", line 1395, in execute_sql
    cursor.execute(sql, params)
  File "/usr/local/lib/python3.10/site-packages/django/db/backends/utils.py", line 103, in execute
    return super().execute(sql, params)
  File "/usr/local/lib/python3.10/site-packages/django/db/backends/utils.py", line 67, in execute
    return self._execute_with_wrappers(
  File "/usr/local/lib/python3.10/site-packages/django/db/backends/utils.py", line 80, in _execute_with_wrappers
    return executor(sql, params, many, context)
  File "/usr/local/lib/python3.10/site-packages/django/db/backends/utils.py", line 84, in _execute
    with self.db.wrap_database_errors:
  File "/usr/local/lib/python3.10/site-packages/django/db/utils.py", line 91, in __exit__
    raise dj_exc_value.with_traceback(traceback) from exc_value
  File "/usr/local/lib/python3.10/site-packages/django/db/backends/utils.py", line 89, in _execute
    return self.cursor.execute(sql, params)
  File "/usr/local/lib/python3.10/site-packages/django/db/backends/sqlite3/base.py", line 357, in execute
    return Database.Cursor.execute(self, query, params)
django.db.utils.OperationalError: no such table: mailing_mailing
2022-12-13 03:12:20,136 django.request WARNING  Not Found: /favicon.ico
2022-12-13 03:12:27,834 django.request ERROR    Internal Server Error: /api/mailing/
Traceback (most recent call last):
  File "/usr/local/lib/python3.10/site-packages/django/db/backends/utils.py", line 89, in _execute
    return self.cursor.execute(sql, params)
  File "/usr/local/lib/python3.10/site-packages/django/db/backends/sqlite3/base.py", line 357, in execute
    return Database.Cursor.execute(self, query, params)
sqlite3.OperationalError: no such table: mailing_mailing

The above exception was the direct cause of the following exception:

Traceback (most recent call last):
  File "/usr/local/lib/python3.10/site-packages/django/core/handlers/exception.py", line 55, in inner
    response = get_response(request)
  File "/usr/local/lib/python3.10/site-packages/django/core/handlers/base.py", line 197, in _get_response
    response = wrapped_callback(request, *callback_args, **callback_kwargs)
  File "/usr/local/lib/python3.10/site-packages/django/views/decorators/csrf.py", line 54, in wrapped_view
    return view_func(*args, **kwargs)
  File "/usr/local/lib/python3.10/site-packages/rest_framework/viewsets.py", line 125, in view
    return self.dispatch(request, *args, **kwargs)
  File "/usr/local/lib/python3.10/site-packages/rest_framework/views.py", line 509, in dispatch
    response = self.handle_exception(exc)
  File "/usr/local/lib/python3.10/site-packages/rest_framework/views.py", line 469, in handle_exception
    self.raise_uncaught_exception(exc)
  File "/usr/local/lib/python3.10/site-packages/rest_framework/views.py", line 480, in raise_uncaught_exception
    raise exc
  File "/usr/local/lib/python3.10/site-packages/rest_framework/views.py", line 506, in dispatch
    response = handler(request, *args, **kwargs)
  File "/usr/local/lib/python3.10/site-packages/rest_framework/mixins.py", line 40, in list
    page = self.paginate_queryset(queryset)
  File "/usr/local/lib/python3.10/site-packages/rest_framework/generics.py", line 171, in paginate_queryset
    return self.paginator.paginate_queryset(queryset, self.request, view=self)
  File "/usr/local/lib/python3.10/site-packages/rest_framework/pagination.py", line 387, in paginate_queryset
    self.count = self.get_count(queryset)
  File "/usr/local/lib/python3.10/site-packages/rest_framework/pagination.py", line 525, in get_count
    return queryset.count()
  File "/usr/local/lib/python3.10/site-packages/django/db/models/query.py", line 621, in count
    return self.query.get_count(using=self.db)
  File "/usr/local/lib/python3.10/site-packages/django/db/models/sql/query.py", line 559, in get_count
    return obj.get_aggregation(using, ["__count"])["__count"]
  File "/usr/local/lib/python3.10/site-packages/django/db/models/sql/query.py", line 544, in get_aggregation
    result = compiler.execute_sql(SINGLE)
  File "/usr/local/lib/python3.10/site-packages/django/db/models/sql/compiler.py", line 1395, in execute_sql
    cursor.execute(sql, params)
  File "/usr/local/lib/python3.10/site-packages/django/db/backends/utils.py", line 103, in execute
    return super().execute(sql, params)
  File "/usr/local/lib/python3.10/site-packages/django/db/backends/utils.py", line 67, in execute
    return self._execute_with_wrappers(
  File "/usr/local/lib/python3.10/site-packages/django/db/backends/utils.py", line 80, in _execute_with_wrappers
    return executor(sql, params, many, context)
  File "/usr/local/lib/python3.10/site-packages/django/db/backends/utils.py", line 84, in _execute
    with self.db.wrap_database_errors:
  File "/usr/local/lib/python3.10/site-packages/django/db/utils.py", line 91, in __exit__
    raise dj_exc_value.with_traceback(traceback) from exc_value
  File "/usr/local/lib/python3.10/site-packages/django/db/backends/utils.py", line 89, in _execute
    return self.cursor.execute(sql, params)
  File "/usr/local/lib/python3.10/site-packages/django/db/backends/sqlite3/base.py", line 357, in execute
    return Database.Cursor.execute(self, query, params)
django.db.utils.OperationalError: no such table: mailing_mailing
2022-12-13 03:13:47,452 django.utils.autoreload INFO     /FabricaResheniy/FabricaResheniy/settings.py changed, reloading.
2022-12-13 03:14:00,635 django.utils.autoreload INFO     Watching for file changes with StatReloader
2022-12-13 03:14:20,378 django.request ERROR    Internal Server Error: /api/mailing/
Traceback (most recent call last):
  File "/usr/local/lib/python3.10/site-packages/django/db/backends/utils.py", line 89, in _execute
    return self.cursor.execute(sql, params)
  File "/usr/local/lib/python3.10/site-packages/django/db/backends/sqlite3/base.py", line 357, in execute
    return Database.Cursor.execute(self, query, params)
sqlite3.OperationalError: no such table: mailing_mailing

The above exception was the direct cause of the following exception:

Traceback (most recent call last):
  File "/usr/local/lib/python3.10/site-packages/django/core/handlers/exception.py", line 55, in inner
    response = get_response(request)
  File "/usr/local/lib/python3.10/site-packages/django/core/handlers/base.py", line 197, in _get_response
    response = wrapped_callback(request, *callback_args, **callback_kwargs)
  File "/usr/local/lib/python3.10/site-packages/django/views/decorators/csrf.py", line 54, in wrapped_view
    return view_func(*args, **kwargs)
  File "/usr/local/lib/python3.10/site-packages/rest_framework/viewsets.py", line 125, in view
    return self.dispatch(request, *args, **kwargs)
  File "/usr/local/lib/python3.10/site-packages/rest_framework/views.py", line 509, in dispatch
    response = self.handle_exception(exc)
  File "/usr/local/lib/python3.10/site-packages/rest_framework/views.py", line 469, in handle_exception
    self.raise_uncaught_exception(exc)
  File "/usr/local/lib/python3.10/site-packages/rest_framework/views.py", line 480, in raise_uncaught_exception
    raise exc
  File "/usr/local/lib/python3.10/site-packages/rest_framework/views.py", line 506, in dispatch
    response = handler(request, *args, **kwargs)
  File "/usr/local/lib/python3.10/site-packages/rest_framework/mixins.py", line 40, in list
    page = self.paginate_queryset(queryset)
  File "/usr/local/lib/python3.10/site-packages/rest_framework/generics.py", line 171, in paginate_queryset
    return self.paginator.paginate_queryset(queryset, self.request, view=self)
  File "/usr/local/lib/python3.10/site-packages/rest_framework/pagination.py", line 387, in paginate_queryset
    self.count = self.get_count(queryset)
  File "/usr/local/lib/python3.10/site-packages/rest_framework/pagination.py", line 525, in get_count
    return queryset.count()
  File "/usr/local/lib/python3.10/site-packages/django/db/models/query.py", line 621, in count
    return self.query.get_count(using=self.db)
  File "/usr/local/lib/python3.10/site-packages/django/db/models/sql/query.py", line 559, in get_count
    return obj.get_aggregation(using, ["__count"])["__count"]
  File "/usr/local/lib/python3.10/site-packages/django/db/models/sql/query.py", line 544, in get_aggregation
    result = compiler.execute_sql(SINGLE)
  File "/usr/local/lib/python3.10/site-packages/django/db/models/sql/compiler.py", line 1395, in execute_sql
    cursor.execute(sql, params)
  File "/usr/local/lib/python3.10/site-packages/django/db/backends/utils.py", line 103, in execute
    return super().execute(sql, params)
  File "/usr/local/lib/python3.10/site-packages/django/db/backends/utils.py", line 67, in execute
    return self._execute_with_wrappers(
  File "/usr/local/lib/python3.10/site-packages/django/db/backends/utils.py", line 80, in _execute_with_wrappers
    return executor(sql, params, many, context)
  File "/usr/local/lib/python3.10/site-packages/django/db/backends/utils.py", line 84, in _execute
    with self.db.wrap_database_errors:
  File "/usr/local/lib/python3.10/site-packages/django/db/utils.py", line 91, in __exit__
    raise dj_exc_value.with_traceback(traceback) from exc_value
  File "/usr/local/lib/python3.10/site-packages/django/db/backends/utils.py", line 89, in _execute
    return self.cursor.execute(sql, params)
  File "/usr/local/lib/python3.10/site-packages/django/db/backends/sqlite3/base.py", line 357, in execute
    return Database.Cursor.execute(self, query, params)
django.db.utils.OperationalError: no such table: mailing_mailing
2022-12-13 03:17:06,880 django.utils.autoreload INFO     Watching for file changes with StatReloader
2022-12-13 03:20:23,851 django.request WARNING  Not Found: /favicon.ico
2022-12-13 03:21:31,515 mailing.views INFO     Клиент создан с phone: 79533068500
2022-12-13 03:21:57,496 mailing.views INFO     Клиент создан с phone: 79513068501
2022-12-13 03:22:32,343 mailing.views INFO     Рассылка создана с ID: 1
2022-12-13 03:22:32,507 mailing.tools INFO     Передача данных на отправку клиентам: [<Client: Client 79533068500>]
2022-12-13 03:23:05,254 mailing.views INFO     Рассылка успешно обновлена с ID: 1
2022-12-13 03:23:05,271 mailing.tools INFO     Передача данных на отправку клиентам: [<Client: Client 79533068500>]
2022-12-13 03:25:32,261 mailing.views INFO     Рассылка успешно обновлена с ID: 1
2022-12-13 03:25:32,279 mailing.tools INFO     Передача данных на отправку клиентам: [<Client: Client 79533068500>]
2022-12-13 04:02:37,077 django.utils.autoreload INFO     /FabricaResheniy/mailing/views.py changed, reloading.
2022-12-13 04:02:52,728 django.utils.autoreload INFO     Watching for file changes with StatReloader
2022-12-13 04:07:09,390 django.utils.autoreload INFO     /FabricaResheniy/mailing/views.py changed, reloading.
2022-12-13 04:07:22,739 django.utils.autoreload INFO     Watching for file changes with StatReloader
2022-12-13 04:08:26,702 django.utils.autoreload INFO     /FabricaResheniy/mailing/views.py changed, reloading.
2022-12-13 04:08:32,007 django.utils.autoreload INFO     Watching for file changes with StatReloader
2022-12-13 04:09:06,641 mailing.views INFO     Рассылка создана с ID: 2
2022-12-13 04:09:06,705 mailing.tools INFO     Передача данных на отправку клиентам: []
2022-12-13 04:10:53,822 mailing.views INFO     Рассылка успешно обновлена с ID: 2
2022-12-13 04:10:53,844 mailing.tools INFO     Передача данных на отправку клиентам: []
2022-12-13 04:11:06,827 mailing.views INFO     Рассылка успешно обновлена с ID: 2
2022-12-13 04:11:07,037 mailing.tools INFO     Передача данных на отправку клиентам: [<Client: Client 79533068500>]
2022-12-13 04:11:51,115 django.request ERROR    Internal Server Error: /api/mailing/2/
Traceback (most recent call last):
  File "/usr/local/lib/python3.10/site-packages/django/core/handlers/exception.py", line 55, in inner
    response = get_response(request)
  File "/usr/local/lib/python3.10/site-packages/django/core/handlers/base.py", line 197, in _get_response
    response = wrapped_callback(request, *callback_args, **callback_kwargs)
  File "/usr/local/lib/python3.10/site-packages/django/views/decorators/csrf.py", line 54, in wrapped_view
    return view_func(*args, **kwargs)
  File "/usr/local/lib/python3.10/site-packages/rest_framework/viewsets.py", line 125, in view
    return self.dispatch(request, *args, **kwargs)
  File "/usr/local/lib/python3.10/site-packages/rest_framework/views.py", line 509, in dispatch
    response = self.handle_exception(exc)
  File "/usr/local/lib/python3.10/site-packages/rest_framework/views.py", line 469, in handle_exception
    self.raise_uncaught_exception(exc)
  File "/usr/local/lib/python3.10/site-packages/rest_framework/views.py", line 480, in raise_uncaught_exception
    raise exc
  File "/usr/local/lib/python3.10/site-packages/rest_framework/views.py", line 506, in dispatch
    response = handler(request, *args, **kwargs)
  File "/FabricaResheniy/mailing/views.py", line 58, in update
    AsyncResult(task_id=tasks_ids).revoke(terminate=True, signal='SIGKILL')
TypeError: AsyncResult.__init__() got an unexpected keyword argument 'task_id'
2022-12-13 04:13:35,146 django.utils.autoreload INFO     /FabricaResheniy/mailing/views.py changed, reloading.
2022-12-13 04:13:47,886 django.utils.autoreload INFO     Watching for file changes with StatReloader
2022-12-13 04:14:19,346 mailing.views INFO     Рассылка успешно обновлена с ID: 2
2022-12-13 04:14:19,360 mailing.tools INFO     Передача данных на отправку клиентам: [<Client: Client 79533068500>]
2022-12-13 04:27:52,799 mailing.views INFO     Рассылка создана с ID: 3
2022-12-13 04:27:53,191 mailing.tools INFO     Передача данных на отправку клиентам: [<Client: Client 79533068500>]
2022-12-13 04:28:32,036 mailing.views INFO     Рассылка успешно обновлена с ID: 3
2022-12-13 04:28:32,052 mailing.tools INFO     Передача данных на отправку клиентам: [<Client: Client 79533068500>]
2022-12-13 04:52:09,664 mailing.views INFO     Рассылка создана с ID: 4
2022-12-13 04:52:09,841 mailing.tools INFO     Передача данных на отправку клиентам: [<Client: Client 79533068500>]
2022-12-13 04:52:57,505 mailing.views ERROR    Ошибка при обновлении рассылки, {'start_date': [ErrorDetail(string='Datetime has wrong format. Use one of these formats instead: YYYY-MM-DDThh:mm[:ss[.uuuuuu]][+HH:MM|-HH:MM|Z].', code='invalid')], 'end_date': [ErrorDetail(string='Datetime has wrong format. Use one of these formats instead: YYYY-MM-DDThh:mm[:ss[.uuuuuu]][+HH:MM|-HH:MM|Z].', code='invalid')]}
2022-12-13 04:52:57,534 django.request WARNING  Bad Request: /api/mailing/4/
2022-12-13 04:53:11,622 mailing.views INFO     Рассылка успешно обновлена с ID: 4
2022-12-13 04:53:11,627 mailing.tools INFO     Передача данных на отправку клиентам: [<Client: Client 79533068500>, <Client: Client 79513068501>]
2022-12-13 05:56:59,718 django.utils.autoreload INFO     Watching for file changes with StatReloader
2022-12-13 06:13:00,694 mailing.views INFO     Рассылка создана с ID: 5
2022-12-13 06:13:00,882 mailing.tools INFO     Передача данных на отправку клиентам: [<Client: Client 79533068500>, <Client: Client 79513068501>]
2022-12-13 06:13:24,781 mailing.views INFO     Рассылка удалена с ID: 5
2022-12-13 06:14:34,506 mailing.views INFO     Клиент создан с phone: 79111068501
2022-12-13 06:14:56,450 django.request WARNING  Not Found: /api/client/11/
2022-12-13 06:15:11,811 mailing.views INFO     Клиент обновлён с id: 3
2022-12-13 06:15:19,129 mailing.views INFO     Клиент обновлён с id: 3
2022-12-13 06:15:19,130 mailing.views INFO     Клиент обновлён с id: 3
2022-12-13 06:15:30,789 mailing.views INFO     Клиент удалён с id: 3
2022-12-13 06:25:55,211 django.utils.autoreload INFO     Watching for file changes with StatReloader
2022-12-13 06:33:52,096 django.request WARNING  Not Found: /swagger/
2022-12-13 06:33:57,939 django.request WARNING  Not Found: /docs
2022-12-13 06:36:15,435 mailing.views INFO     Рассылка успешно обновлена с ID: 1
2022-12-13 06:36:15,444 mailing.tools INFO     Передача данных на отправку клиентам: []
2022-12-13 06:37:08,989 django.request WARNING  Bad Request: /api/message/1/
